Workbook
Name FaAx: '[1]Site Coefficients (BSE-2N)'!$K$7:$K$13
Name FaAx: 'Site Coefficients'!$L$9:$L$15
Name FaAy: 'Site Coefficients'!$M$9:$M$15
Name FaBx: '[1]Site Coefficients (BSE-2N)'!$M$7:$M$13
Name FaBx: 'Site Coefficients'!$N$9:$N$15
Name FaBy: 'Site Coefficients'!$O$9:$O$15
Name FaCx: '[1]Site Coefficients (BSE-2N)'!$O$7:$O$13
Name FaCx: 'Site Coefficients'!$P$9:$P$15
Name FaCy: '[1]Site Coefficients (BSE-2N)'!$P$7:$P$13
Name FaCy: 'Site Coefficients'!$Q$9:$Q$15
Name FaDx: '[1]Site Coefficients (BSE-2N)'!$Q$7:$Q$13
Name FaDx: 'Site Coefficients'!$R$9:$R$15
Name FaDy: '[1]Site Coefficients (BSE-2N)'!$R$7:$R$13
Name FaDy: 'Site Coefficients'!$S$9:$S$15
Name FaEx: '[1]Site Coefficients (BSE-2N)'!$S$7:$S$13
Name FaEx: 'Site Coefficients'!$T$9:$T$15
Name FaEy: '[1]Site Coefficients (BSE-2N)'!$T$7:$T$13
Name FaEy: 'Site Coefficients'!$U$9:$U$15
Name FvAx: '[1]Site Coefficients (BSE-2N)'!$K$22:$K$28
Name FvAx: 'Site Coefficients'!$L$22:$L$28
Name FvAy: 'Site Coefficients'!$M$22:$M$28
Name FvBx: '[1]Site Coefficients (BSE-2N)'!$M$22:$M$28
Name FvBx: 'Site Coefficients'!$N$22:$N$28
Name FvBy: 'Site Coefficients'!$O$22:$O$28
Name FvCx: '[1]Site Coefficients (BSE-2N)'!$O$22:$O$28
Name FvCx: 'Site Coefficients'!$P$22:$P$28
Name FvCy: '[1]Site Coefficients (BSE-2N)'!$P$22:$P$28
Name FvCy: 'Site Coefficients'!$Q$22:$Q$28
Name FvDx: '[1]Site Coefficients (BSE-2N)'!$Q$22:$Q$28
Name FvDx: 'Site Coefficients'!$R$22:$R$28
Name FvDy: '[1]Site Coefficients (BSE-2N)'!$R$22:$R$28
Name FvDy: 'Site Coefficients'!$S$22:$S$28
Name FvEx: '[1]Site Coefficients (BSE-2N)'!$S$22:$S$28
Name FvEx: 'Site Coefficients'!$T$22:$T$28
Name FvEy: '[1]Site Coefficients (BSE-2N)'!$T$22:$T$28
Name FvEy: 'Site Coefficients'!$U$22:$U$28
Name MatchFaA: 'Site Coefficients'!$M$17
Name MatchFaB: 'Site Coefficients'!$O$17
Name MatchFaC: '[1]Site Coefficients (BSE-2N)'!$P$15
Name MatchFaC: 'Site Coefficients'!$Q$17
Name MatchFaD: '[1]Site Coefficients (BSE-2N)'!$R$15
Name MatchFaD: 'Site Coefficients'!$S$17
Name MatchFaE: '[1]Site Coefficients (BSE-2N)'!$T$15
Name MatchFaE: 'Site Coefficients'!$U$17
Name MatchFvA: 'Site Coefficients'!$M$30
Name MatchFvB: 'Site Coefficients'!$O$30
Name MatchFvC: '[1]Site Coefficients (BSE-2N)'!$P$30
Name MatchFvC: 'Site Coefficients'!$Q$30
Name MatchFvD: '[1]Site Coefficients (BSE-2N)'!$R$30
Name MatchFvD: 'Site Coefficients'!$S$30
Name MatchFvE: '[1]Site Coefficients (BSE-2N)'!$T$30
Name MatchFvE: 'Site Coefficients'!$U$30
Name SiteClass: 'Site Coefficients'!$L$34:$L$38
Name TargetFaA: '[1]Site Coefficients (BSE-2N)'!$L$14
Name TargetFaA: 'Site Coefficients'!$M$16
Name TargetFaB: '[1]Site Coefficients (BSE-2N)'!$N$14
Name TargetFaB: 'Site Coefficients'!$O$16
Name TargetFaC: '[1]Site Coefficients (BSE-2N)'!$P$14
Name TargetFaC: 'Site Coefficients'!$Q$16
Name TargetFaD: '[1]Site Coefficients (BSE-2N)'!$R$14

Sheet Site Ground Motions
D1: Project: | H1: By: | J1: Sheet No. | L1: GRAY AREA USED FOR NOTES TO ENGINEER OR BACK-UP CALCS (DOES NOT PRINT) | W1: Template version: | X1: 2.1
D2: Location: | H2: Date: | J2: 1 of 5 | W2: Last updated: | X2: 45201
D3: Client: | H3: Revised: | J3: Job No.
D4: Subject: | E4: SITE GROUND MOTIONS | H4: Date:
A6: SITE GROUND MOTIONS PER ASCE 7-16, Chapters 11 and 12 | L6: FORMATTING LEGEND
M7: Blank highlighted cell = requires engineer input to run.
B8: Use Site Class: | C8: D | E8: Per geotechnical report dated July 1, 2025 | L8: 888 | M8: Shaded cell = value requires engineer review/input.
B9: Latitude = | C9: 45.602979 | L9: 1.05 | M9: Bold red indicates design warning.
B10: Longitude = | C10: -124.046
B12: SS = | C12: 0.887 | E12: Per Tramell Geotech Report
B13: S1 = | C13: 0.41 | E13: Per Tramell Geotech Report
B14: Fa = | C14: ='Site Coefficients'!C39 -> 1.1452 | E14: { From Table 11.4-1 }
B15: Fv = | C15: ='Site Coefficients'!C40 -> 1.89 | E15: { From Table 11.4-2 }
C16: =+IF(AND(C8="D",C13>=0.2),"See Section 11.4.8 - Design spectrum values increased to meet exception","") -> See Section 11.4.8 - Design spectrum values increased to meet exception
B17: SMS = | C17: =+C12*C14 -> 1.0157924 | E17: { Per ASCE 7-16 SMS = SS * Fa }
B18: SM1 = | C18: =+C13*C15 -> 0.7749 | E18: { Per ASCE 7-16 SM1 = S1 * Fv }
L19: Does Not Print
L20: T | M20: Sa | N20: T | O20: Sa | Q20: Building Period
B21: SDS = | C21: =+C17*2/3 -> 0.67719493 | E21: { Per ASCE 7-16 SDS = 2/3 SMS } | L21: 0 | M21: =0.4 * C21 -> 0.27087797 | N21: 0 | O21: =0.4 * C21 -> 0.27087797 | Q21: 0 | R21: =C39 -> 0.44921739
B22: SD1 = | C22: =+C18*2/3 -> 0.5166 | E22: { Per ASCE 7-16 SD1 = 2/3 SM1 } | L22: =C24 -> 0.15257054 | M22: =C21 -> 0.67719493 | N22: =+C24 -> 0.15257054 | O22: =C21 -> 0.67719493 | Q22: =C33 -> 1.15 | R22: =C39 -> 0.44921739
L23: =+C25 -> 0.76285272 | M23: =C21 -> 0.67719493 | N23: =IF(AND(C8="D",C13>=0.2),1.5*C25,C25) -> 1.1442791 | O23: =C21 -> 0.67719493 | Q23: =C33 -> 1.15 | R23: 0
B24: T0 = | C24: =0.2 * C25 -> 0.15257054 | E24: { T0 = 0.2 * TS } | L24: =ROUNDUP(L23 + 0.00001,1) -> 0.8 | M24: =+IF(L24>$C$26,$C$22*$C$26/L24^2,$C$22 / L24) -> 0.64575 | N24: =ROUNDUP(N23 + 0.00001,1) -> 1.2 | O24: =IF(AND($C$8="D",$C$13>=0.2),1.5*IF(N24>$C$26,$C$22*$C$26/N24^2,$C$22 / N24),IF(N24>$C$26,$C$22*$C$26/N24^2,$C$22 / N24)) -> 0.64575
B25: TS = | C25: =C22 / C21 -> 0.76285272 | E25: { TS = SD1 / SDS } | L25: =L24 + 0.1 -> 0.9 | M25: =+IF(L25>$C$26,$C$22*$C$26/L25^2,$C$22 / L25) -> 0.574 | N25: =N24 + 0.1 -> 1.3 | O25: =IF(AND($C$8="D",$C$13>=0.2),1.5*IF(N25>$C$26,$C$22*$C$26/N25^2,$C$22 / N25),IF(N25>$C$26,$C$22*$C$26/N25^2,$C$22 / N25)) -> 0.59607692
B26: TL = | C26: 16 | E26: { From Chapter 22 } | L26: =L25 + 0.1 -> 1 | M26: =+IF(L26>$C$26,$C$22*$C$26/L26^2,$C$22 / L26) -> 0.5166 | N26: =N25 + 0.1 -> 1.4 | O26: =IF(AND($C$8="D",$C$13>=0.2),1.5*IF(N26>$C$26,$C$22*$C$26/N26^2,$C$22 / N26),IF(N26>$C$26,$C$22*$C$26/N26^2,$C$22 / N26)) -> 0.5535 | Q26: =C24 -> 0.15257054 | R26: 0
L27: =L26 + 0.1 -> 1.1 | M27: =+IF(L27>$C$26,$C$22*$C$26/L27^2,$C$22 / L27) -> 0.46963636 | N27: =N26 + 0.1 -> 1.5 | O27: =IF(AND($C$8="D",$C$13>=0.2),1.5*IF(N27>$C$26,$C$22*$C$26/N27^2,$C$22 / N27),IF(N27>$C$26,$C$22*$C$26/N27^2,$C$22 / N27)) -> 0.5166 | Q27: =C24 -> 0.15257054 | R27: =C21 -> 0.67719493
B28: hn = | C28: ='Vertical Distribution'!D18 -> 42.5 | E28: { Building above base to roof level, see Vertical Distribution sheet } | L28: =L27 + 0.1 -> 1.2 | M28: =+IF(L28>$C$26,$C$22*$C$26/L28^2,$C$22 / L28) -> 0.4305 | N28: =N27 + 0.1 -> 1.6 | O28: =IF(AND($C$8="D",$C$13>=0.2),1.5*IF(N28>$C$26,$C$22*$C$26/N28^2,$C$22 / N28),IF(N28>$C$26,$C$22*$C$26/N28^2,$C$22 / N28)) -> 0.4843125
B29: Ta = | C29: =0.02*((C28))^0.75 -> 0.33290605 | E29: { Building Period per ASCE 7-16 Eq. 12.8-7 } | L29: =L28 + 0.1 -> 1.3 | M29: =+IF(L29>$C$26,$C$22*$C$26/L29^2,$C$22 / L29) -> 0.39738462 | N29: =N28 + 0.1 -> 1.7 | O29: =IF(AND($C$8="D",$C$13>=0.2),1.5*IF(N29>$C$26,$C$22*$C$26/N29^2,$C$22 / N29),IF(N29>$C$26,$C$22*$C$26/N29^2,$C$22 / N29)) -> 0.45582353
B30: or Ta = | C30: n/a | E30: { Alternate Building Period per Eq. 12.8-8 or 12.8-9 if applicable } | L30: =L29 + 0.1 -> 1.4 | M30: =+IF(L30>$C$26,$C$22*$C$26/L30^2,$C$22 / L30) -> 0.369 | N30: =N29 + 0.1 -> 1.8 | O30: =IF(AND($C$8="D",$C$13>=0.2),1.5*IF(N30>$C$26,$C$22*$C$26/N30^2,$C$22 / N30),IF(N30>$C$26,$C$22*$C$26/N30^2,$C$22 / N30)) -> 0.4305 | Q30: =C25 -> 0.76285272 | R30: 0
B31: T = | C31: n/a | E31: { Building Period from Dynamic Analysis } | L31: =L30 + 0.1 -> 1.5 | M31: =+IF(L31>$C$26,$C$22*$C$26/L31^2,$C$22 / L31) -> 0.3444 | N31: =N30 + 0.1 -> 1.9 | O31: =IF(AND($C$8="D",$C$13>=0.2),1.5*IF(N31>$C$26,$C$22*$C$26/N31^2,$C$22 / N31),IF(N31>$C$26,$C$22*$C$26/N31^2,$C$22 / N31)) -> 0.40784211 | Q31: =C25 -> 0.76285272 | R31: =C21 -> 0.67719493 | T31: Note: dyamic analysis is required to use Cu * T.
B32: Cu = | C32: 1 | E32: { Coefficient for Upper Limit on Calculated Period from Table 12.8-1 } | L32: =L31 + 0.1 -> 1.6 | M32: =+IF(L32>$C$26,$C$22*$C$26/L32^2,$C$22 / L32) -> 0.322875 | N32: =N31 + 0.1 -> 2 | O32: =IF(AND($C$8="D",$C$13>=0.2),1.5*IF(N32>$C$26,$C$22*$C$26/N32^2,$C$22 / N32),IF(N32>$C$26,$C$22*$C$26/N32^2,$C$22 / N32)) -> 0.38745
B33: USE T = | C33: 1.15 | E33: { Include Upperbound Limit on T per ASCE 7-16, Section 12.8.2 } | L33: =L32 + 0.1 -> 1.7 | M33: =+IF(L33>$C$26,$C$22*$C$26/L33^2,$C$22 / L33) -> 0.30388235 | N33: =N32 + 0.1 -> 2.1 | O33: =IF(AND($C$8="D",$C$13>=0.2),1.5*IF(N33>$C$26,$C$22*$C$26/N33^2,$C$22 / N33),IF(N33>$C$26,$C$22*$C$26/N33^2,$C$22 / N33)) -> 0.369 | Q33: =C26 -> 16 | R33: 0 | T33: Select either Ta per EQ 12.8-7/8/9, or min(T_dyanmic, Cu * Ta).
L34: =L33 + 0.1 -> 1.8 | M34: =+IF(L34>$C$26,$C$22*$C$26/L34^2,$C$22 / L34) -> 0.287 | N34: =N33 + 0.1 -> 2.2 | O34: =IF(AND($C$8="D",$C$13>=0.2),1.5*IF(N34>$C$26,$C$22*$C$26/N34^2,$C$22 / N34),IF(N34>$C$26,$C$22*$C$26/N34^2,$C$22 / N34)) -> 0.35222727 | Q34: =C26 -> 16 | R34: =C22 / C26 -> 0.0322875
B35: Sa = | C35: =C21 * (0.4 + 0.6 * C33 / C24) -> 3.3334908 | E35: { Sa = SDS* (0.4 + 0.6 T / T0) for (T < T0) per Section 11.4.5.1 } | L35: =L34 + 0.1 -> 1.9 | M35: =+IF(L35>$C$26,$C$22*$C$26/L35^2,$C$22 / L35) -> 0.27189474 | N35: =N34 + 0.1 -> 2.3 | O35: =IF(AND($C$8="D",$C$13>=0.2),1.5*IF(N35>$C$26,$C$22*$C$26/N35^2,$C$22 / N35),IF(N35>$C$26,$C$22*$C$26/N35^2,$C$22 / N35)) -> 0.33691304
B36: or Sa = | C36: =C21 -> 0.67719493 | E36: { Sa = SDS for (T0 < T < TS) per Section 11.4.5.2 } | L36: =L35 + 0.1 -> 2 | M36: =+IF(L36>$C$26,$C$22*$C$26/L36^2,$C$22 / L36) -> 0.2583 | N36: =N35 + 0.1 -> 2.4 | O36: =IF(AND($C$8="D",$C$13>=0.2),1.5*IF(N36>$C$26,$C$22*$C$26/N36^2,$C$22 / N36),IF(N36>$C$26,$C$22*$C$26/N36^2,$C$22 / N36)) -> 0.322875
B37: or Sa = | C37: =C22 / C33 -> 0.44921739 | E37: { Sa = SD1 / T for (T > TS) per Section 11.4.5.3 } | L37: =L36 + 0.1 -> 2.1 | M37: =+IF(L37>$C$26,$C$22*$C$26/L37^2,$C$22 / L37) -> 0.246 | N37: =N36 + 0.1 -> 2.5 | O37: =IF(AND($C$8="D",$C$13>=0.2),1.5*IF(N37>$C$26,$C$22*$C$26/N37^2,$C$22 / N37),IF(N37>$C$26,$C$22*$C$26/N37^2,$C$22 / N37)) -> 0.30996
B38: or Sa = | C38: =C22 * C26 / C33^2 -> 6.2499811 | E38: { Sa = SD1 * TL / T2 for (T > TL) per Section 11.4.5.4 } | L38: =L37 + 0.1 -> 2.2 | M38: =+IF(L38>$C$26,$C$22*$C$26/L38^2,$C$22 / L38) -> 0.23481818 | N38: =N37 + 0.1 -> 2.6 | O38: =IF(AND($C$8="D",$C$13>=0.2),1.5*IF(N38>$C$26,$C$22*$C$26/N38^2,$C$22 / N38),IF(N38>$C$26,$C$22*$C$26/N38^2,$C$22 / N38)) -> 0.29803846
B39: USE Sa = | C39: =IF(C33 < C24, C35, IF(AND(C33 > C24, C33 < C25), C36, IF(AND(C33 > C25, C33 < C26), C37, C38))) -> 0.44921739 | L39: =L38 + 0.1 -> 2.3 | M39: =+IF(L39>$C$26,$C$22*$C$26/L39^2,$C$22 / L39) -> 0.2246087 | N39: =N38 + 0.1 -> 2.7 | O39: =IF(AND($C$8="D",$C$13>=0.2),1.5*IF(N39>$C$26,$C$22*$C$26/N39^2,$C$22 / N39),IF(N39>$C$26,$C$22*$C$26/N39^2,$C$22 / N39)) -> 0.287
L40: =L39 + 0.2 -> 2.5 | M40: =+IF(L40>$C$26,$C$22*$C$26/L40^2,$C$22 / L40) -> 0.20664 | N40: =N39 + 0.2 -> 2.9 | O40: =IF(AND($C$8="D",$C$13>=0.2),1.5*IF(N40>$C$26,$C$22*$C$26/N40^2,$C$22 / N40),IF(N40>$C$26,$C$22*$C$26/N40^2,$C$22 / N40)) -> 0.2672069
L41: =L40 + 0.2 -> 2.7 | M41: =+IF(L41>$C$26,$C$22*$C$26/L41^2,$C$22 / L41) -> 0.19133333 | N41: =N40 + 0.2 -> 3.1 | O41: =IF(AND($C$8="D",$C$13>=0.2),1.5*IF(N41>$C$26,$C$22*$C$26/N41^2,$C$22 / N41),IF(N41>$C$26,$C$22*$C$26/N41^2,$C$22 / N41)) -> 0.24996774
L42: =L41 + 0.2 -> 2.9 | M42: =+IF(L42>$C$26,$C$22*$C$26/L42^2,$C$22 / L42) -> 0.17813793 | N42: =N41 + 0.2 -> 3.3 | O42: =IF(AND($C$8="D",$C$13>=0.2),1.5*IF(N42>$C$26,$C$22*$C$26/N42^2,$C$22 / N42),IF(N42>$C$26,$C$22*$C$26/N42^2,$C$22 / N42)) -> 0.23481818
...

Sheet Site Coefficients
D1: Project: | E1: =+IF('Site Ground Motions'!E1="","",'Site Ground Motions'!E1) | H1: By: | I1: =+IF('Site Ground Motions'!I1="","",'Site Ground Motions'!I1) | J1: Sheet No. | L1: GRAY AREA USED FOR NOTES TO ENGINEER OR BACK-UP CALCS (DOES NOT PRINT) | W1: Template version: | X1: ='Site Ground Motions'!X1 -> 2.1
D2: Location: | E2: =+IF('Site Ground Motions'!E2="","",'Site Ground Motions'!E2) | H2: Date: | I2: =+IF('Site Ground Motions'!I2="","",'Site Ground Motions'!I2) | J2: 2 of 5 | L2: * NOTE: TITLEBLOCK INFORMATION REFERENCES "SITE GROUND MOTION" PAGE | W2: Last updated: | X2: ='Site Ground Motions'!X2 -> 45201
D3: Client: | E3: =+IF('Site Ground Motions'!E3="","",'Site Ground Motions'!E3) | H3: Revised: | I3: =+IF('Site Ground Motions'!I3="","",'Site Ground Motions'!I3) | J3: Job No.
D4: Subject: | E4: SITE COEFFICIENTS | H4: Date: | I4: =+IF('Site Ground Motions'!I4="","",'Site Ground Motions'!I4) | J4: =+IF('Site Ground Motions'!J4="","",'Site Ground Motions'!J4) | L4: FORMATTING LEGEND
M5: Blank highlighted cell = requires engineer input to run.
A6: SITE COEFFICIENTS PER ASCE 7-16, Chapter 11 | L6: 888 | M6: Shaded cell = value requires engineer review/input.
L7: 1.05 | M7: Bold red indicates design warning.
B8: TABLE 11.4-1 SITE COEFFICIENT, Fa
L9: 0 | M9: 0.8 | N9: 0 | O9: 0.9 | P9: 0 | Q9: 1.3 | R9: 0 | S9: 1.6 | T9: 0 | U9: 2.4
C10: Mapped Risk-Targeted MCER | L10: 0.25 | M10: 0.8 | N10: 0.25 | O10: 0.9 | P10: 0.25 | Q10: 1.3 | R10: 0.25 | S10: 1.6 | T10: 0.25 | U10: 2.4
C11: Spectral Response Acceleration Parameter at Short Period | K11: Note: Fv is pulled from the 2022 OSSC. Scaling per 11.4.8 is still required unless we have site-specific values from a geotechnical report | L11: 0.5 | M11: 0.8 | N11: 0.5 | O11: 0.9 | P11: 0.5 | Q11: 1.3 | R11: 0.5 | S11: 1.4 | T11: 0.5 | U11: 1.7
B12: Site Class | C12: 0.25 | D12: 0.5 | E12: 0.75 | F12: 1 | G12: 1.25 | H12: 1.5 | L12: 0.75 | M12: 0.8 | N12: 0.75 | O12: 0.9 | P12: 0.75 | Q12: 1.2 | R12: 0.75 | S12: 1.2 | T12: 0.75 | U12: 1.3
B13: A | C13: 0.8 | D13: 0.8 | E13: 0.8 | F13: 0.8 | G13: 0.8 | H13: 0.8 | L13: 1 | M13: 0.8 | N13: 1 | O13: 0.9 | P13: 1 | Q13: 1.2 | R13: 1 | S13: 1.1 | T13: 1
B14: B | C14: 0.9 | D14: 0.9 | E14: 0.9 | F14: 0.9 | G14: 0.9 | H14: 0.9 | L14: 1.25 | M14: 0.8 | N14: 1.25 | O14: 0.9 | P14: 1.25 | Q14: 1.2 | R14: 1.25 | S14: 1 | T14: 1.25
B15: C | C15: 1.3 | D15: 1.3 | E15: 1.2 | F15: 1.2 | G15: 1.2 | H15: 1.2 | L15: 1.5 | M15: 0.8 | N15: 1.5 | O15: 0.9 | P15: 1.5 | Q15: 1.2 | R15: 1.5 | S15: 1 | T15: 1.5
B16: D | C16: 1.6 | D16: 1.4 | E16: 1.2 | F16: 1.1 | G16: 1 | H16: 1 | L16: Target | M16: =C36 -> 0.887 | N16: Target | O16: =C36 -> 0.887 | P16: Target | Q16: =C36 -> 0.887 | R16: Target | S16: =C36 -> 0.887 | T16: Target | U16: =C36 -> 0.887
B17: E | C17: 2.4 | D17: 1.7 | E17: 1.3 | F17: See Section 11.4.8 | L17: Match | M17: =MATCH(TargetFaA,FaAx,1) -> 4 | N17: Match | O17: =MATCH(TargetFaB,FaBx,1) -> 4 | P17: Match | Q17: =MATCH(TargetFaC,FaCx,1) -> 4 | R17: Match | S17: =MATCH(TargetFaD,FaDx,1) -> 4 | T17: Match | U17: =MATCH(TargetFaE,FaEx,1) -> 4
B18: F | C18: See Section 11.4.8 | L18: Result | M18: =0.8 -> 0.8 | N18: Result | O18: 0.9 | P18: Result | Q18: =FORECAST(TargetFaC,OFFSET(FaCy,MatchFaC-1,0,2,1),OFFSET(FaCx,MatchFaC-1,0,2,1)) -> 1.2 | R18: Result | S18: =FORECAST(TargetFaD,OFFSET(FaDy,MatchFaD-1,0,2,1),OFFSET(FaDx,MatchFaD-1,0,2,1)) -> 1.1452 | T18: Result | U18: =FORECAST(TargetFaE,OFFSET(FaEy,MatchFaE-1,0,2,1),OFFSET(FaEx,MatchFaE-1,0,2,1)) -> #DIV/0!
B19: NOTE: Use straight-line interpolation for intermediate values of Ss.
B21: TABLE 11.4-2 SITE COEFFICIENT, Fv | L21: FvAx | M21: FvAy | N21: FvBx | O21: FvBy | P21: FvCx | Q21: FvCy | R21: FvDx | S21: FvDy | T21: FvEx | U21: FvEy
L22: 0 | M22: 0.8 | N22: 0 | O22: 0.8 | P22: 0 | Q22: 1.5 | R22: 0 | S22: 2.4 | T22: 0 | U22: 4.2
C23: Mapped Risk-Targeted MCER | L23: 0.1 | M23: 0.8 | N23: 0.1 | O23: 0.8 | P23: 0.1 | Q23: 1.5 | R23: 0.1 | S23: 2.4 | T23: 0.1 | U23: 4.2
C24: Spectral Response Acceleration Parameter at 1-Second Period | L24: 0.2 | M24: 0.8 | N24: 0.2 | O24: 0.8 | P24: 0.2 | Q24: 1.5 | R24: 0.2 | S24: 2.2 | T24: 0.2
B25: Site Class | C25: 0.1 | D25: 0.2 | E25: 0.3 | F25: 0.4 | G25: 0.5 | H25: 0.6 | L25: 0.3 | M25: 0.8 | N25: 0.3 | O25: 0.8 | P25: 0.3 | Q25: 1.5 | R25: 0.3 | S25: 2 | T25: 0.3
B26: A | C26: 0.8 | D26: 0.8 | E26: 0.8 | F26: 0.8 | G26: 0.8 | H26: 0.8 | L26: 0.4 | M26: 0.8 | N26: 0.4 | O26: 0.8 | P26: 0.4 | Q26: 1.5 | R26: 0.4 | S26: 1.9 | T26: 0.4
B27: B | C27: 0.8 | D27: 0.8 | E27: 0.8 | F27: 0.8 | G27: 0.8 | H27: 0.8 | L27: 0.5 | M27: 0.8 | N27: 0.5 | O27: 0.8 | P27: 0.5 | Q27: 1.5 | R27: 0.5 | S27: 1.8 | T27: 0.5
B28: C | C28: 1.5 | D28: 1.5 | E28: 1.5 | F28: 1.5 | G28: 1.5 | H28: 1.4 | L28: 0.6 | M28: 0.8 | N28: 0.6 | O28: 0.8 | P28: 0.6 | Q28: 1.4 | R28: 0.6 | S28: 1.7 | T28: 0.6
B29: D | C29: 2.4 | D29: 2.2 | E29: 2 | F29: 1.9 | G29: 1.8 | H29: 1.7 | L29: Target | M29: =C37 -> 0.41 | N29: Target | O29: =C37 -> 0.41 | P29: Target | Q29: =C37 -> 0.41 | R29: Target | S29: =C37 -> 0.41 | T29: Target | U29: =C37 -> 0.41
B30: E | C30: 4.2 | D30: See Section 11.4.8 | L30: Match | M30: =MATCH(TargetFvA,FvAx,1) -> 5 | N30: Match | O30: =MATCH(TargetFvB,FvBx,1) -> 5 | P30: Match | Q30: =MATCH(TargetFvC,FvCx,1) -> 5 | R30: Match | S30: =MATCH(TargetFvD,FvDx,1) -> 5 | T30: Match | U30: =MATCH(TargetFvE,FvEx,1) -> 5
B31: F | C31: See Section 11.4.8 | L31: Result | M31: =0.8 -> 0.8 | N31: Result | O31: 0.8 | P31: Result | Q31: =FORECAST(TargetFvC,OFFSET(FvCy,MatchFvC-1,0,2,1),OFFSET(FvCx,MatchFvC-1,0,2,1)) -> 1.5 | R31: Result | S31: =FORECAST(TargetFvD,OFFSET(FvDy,MatchFvD-1,0,2,1),OFFSET(FvDx,MatchFvD-1,0,2,1)) -> 1.89 | T31: Result | U31: =FORECAST(TargetFvE,OFFSET(FvEy,MatchFvE-1,0,2,1),OFFSET(FvEx,MatchFvE-1,0,2,1)) -> #DIV/0!
B32: NOTE: Use straight-line interpolation for intermediate values of S1.
M33: Fa | N33: Fv
B34: Site Class = | C34: ='Site Ground Motions'!C8 -> D | L34: A | M34: =M18 -> 0.8 | N34: =M31 -> 0.8
L35: B | M35: =O18 -> 0.9 | N35: =O31 -> 0.8
B36: SS = | C36: ='Site Ground Motions'!C12 -> 0.887 | L36: C | M36: =Q18 -> 1.2 | N36: =Q31 -> 1.5
B37: S1 = | C37: ='Site Ground Motions'!C13 -> 0.41 | L37: D | M37: =S18 -> 1.1452 | N37: =S31 -> 1.89
L38: E | M38: =U18 -> #DIV/0! | N38: =U31 -> #DIV/0!
B39: Fa = | C39: =IFERROR(VLOOKUP(C34,L34:N38,2, FALSE),"Correct the Site Class or Do Site Specific for Site Class D/E/F") -> 1.1452
B40: Fv = | C40: =IFERROR(VLOOKUP(C34,L34:N38,3, FALSE), "Correct the Site Class or Do Site Specific for Site Class D/E/F") -> 1.89

Sheet Equivalent Lateral Forces
D1: Project: | E1: =+IF('Site Ground Motions'!E1="","",'Site Ground Motions'!E1) | K1: By: | L1: =+IF('Site Ground Motions'!I1="","",'Site Ground Motions'!I1) | M1: Sheet No. | O1: GRAY AREA USED FOR NOTES TO ENGINEER OR BACK-UP CALCS (DOES NOT PRINT) | W1: Template version: | X1: ='Site Ground Motions'!X1 -> 2.1
D2: Location: | E2: =+IF('Site Ground Motions'!E2="","",'Site Ground Motions'!E2) | K2: Date: | L2: =+IF('Site Ground Motions'!I2="","",'Site Ground Motions'!I2) | M2: 3 of 5 | O2: * NOTE: TITLEBLOCK INFORMATION REFERENCES "SITE GROUND MOTION" PAGE | W2: Last updated: | X2: ='Site Ground Motions'!X2 -> 45201
D3: Client: | E3: =+IF('Site Ground Motions'!E3="","",'Site Ground Motions'!E3) | K3: Revised: | L3: =+IF('Site Ground Motions'!I3="","",'Site Ground Motions'!I3) | M3: Job No.
D4: Subject: | E4: EQUIVALENT LATERAL FORCES | K4: Date: | L4: =+IF('Site Ground Motions'!I4="","",'Site Ground Motions'!I4) | M4: =+IF('Site Ground Motions'!J4="","",'Site Ground Motions'!J4) | O4: FORMATTING LEGEND
P5: Blank highlighted cell = requires engineer input to run.
A6: EQUIVALENT LATERAL FORCE PROCEDURE PER ASCE 7-16 Section 12.8 | O6: 888 | P6: Shaded cell = value requires engineer review/input.
O7: 1.05 | P7: Bold red indicates design warning.
C9: Risk Category = | D9: II | F9: { From ASCE 7-16, Table 1.5-1 }
C10: Seismic Design Category = | D10: D | F10: { From ASCE 7-16, Section 11.6 } | V10: Period
O11: Does Not Print | V11: ='Site Ground Motions'!Q21 -> 0 | W11: ='Site Ground Motions'!R21 -> 0.44921739 | X11: =+O13 -> 0.10366555
B12: From Site Ground Motions Spreadsheet: | V12: ='Site Ground Motions'!Q22 -> 1.15 | W12: ='Site Ground Motions'!R22 -> 0.44921739 | X12: =+O13 -> 0.10366555
B13: SDS = | C13: ='Site Ground Motions'!C21 -> 0.67719493 | E13: T0 = | F13: ='Site Ground Motions'!C24 -> 0.15257054 | H13: T = | I13: ='Site Ground Motions'!C33 -> 1.15 | O13: =IF(AND(D10="D",C14>0.2),IF(I13 < 1.5*F14, D24, IF(I13 < F15, D26, D28)),IF(I13 < F14, D24, IF(I13 < F15, D25, D27))) -> 0.10366555 | P13: Cs Value determined from 12.8-2 thru 12.8-4. | V13: ='Site Ground Motions'!Q23 -> 1.15 | W13: ='Site Ground Motions'!R23 -> 0 | X13: =W13 / $D$22 -> 0
B14: SD1 = | C14: ='Site Ground Motions'!C22 -> 0.5166 | E14: TS = | F14: ='Site Ground Motions'!C25 -> 0.76285272 | H14: Sa = | I14: ='Site Ground Motions'!C39 -> 0.44921739 | O14: =IF(I15 >= 0.6, "Yes", "No") -> No | P14: = Does 12.8-6 Apply? | V14: Minimum
E15: TL = | F15: ='Site Ground Motions'!C26 -> 16 | H15: S1 = | I15: ='Site Ground Motions'!C13 -> 0.41 | O15: =IF(O14 = "No", D29, MAX(D29, D30)) -> 0.029796577 | P15: = Minimum Value from 12.8-5 and 12.8-6 | V15: ='Site Ground Motions'!L21 -> 0 | W15: =X15*$D$20 -> 0.19367775 | X15: =MAX(D29:D30) -> 0.029796577
V16: =MAX(O23:O58) -> 4.4 | W16: =X16*$D$20 -> 0.19367775 | X16: =MAX(D29:D30) -> 0.029796577
O17: =MAX(O13, O15) -> 0.10366555 | P17: = Cs
C18: V = CsW | F18: { ASCE 7-16 Section 12.8 }
C20: R = | D20: 6.5 | F20: { ASCE 7-16, Table 12.2-1 }
C21: Ie = | D21: 1 | F21: { ASCE 7-16, Table 1.5-2 } | P21: Does Not Print
C22: R / Ie = | D22: =D20 / D21 -> 6.5 | O22: T | P22: Sa | Q22: Cs | V22: T | W22: Cs
O23: ='Site Ground Motions'!L21 -> 0 | P23: N.A. | Q23: =D24 -> 0.10418384 | V23: =O23 -> 0 | W23: =Q23 -> 0.10418384
C24: Cs = | D24: =C13 / D22 -> 0.10418384 | F24: { Cs = SDS / (R / Ie) per Eq. 12.8-2 } | O24: ='Site Ground Motions'!L22 -> 0.15257054 | P24: ='Site Ground Motions'!M22 -> 0.67719493 | Q24: =P24 / $D$22 -> 0.10418384 | V24: =O24 -> 0.15257054 | W24: =Q24 -> 0.10418384
C25: or Cs = | D25: =C14 / I13 / D22 -> 0.069110368 | F25: { Cs = SD1 / T / (R / Ie) Maximum per Eq. 12.8-3 } | O25: =+IF(AND(D10="D",C14>=0.2),1.5*'Site Ground Motions'!L23,'Site Ground Motions'!L23) -> 1.1442791 | P25: ='Site Ground Motions'!M23 -> 0.67719493 | Q25: =P25 / $D$22 -> 0.10418384 | V25: =O25 -> 1.1442791 | W25: =Q25 -> 0.10418384
C26: or Cs = | D26: =1.5*C14 / I13 / D22 -> 0.10366555 | F26: { Cs = 1.5 * SD1 / T / (R / Ie) Maximum per Eq. 12.8-3 and 11.4.8 } | O26: =ROUNDUP(O25 + 0.00001,1) -> 1.2 | P26: =IF(AND($D$10="D",$C$14>=0.2),'Site Ground Motions'!O24,'Site Ground Motions'!M24) -> 0.64575 | Q26: =P26 / $D$22 -> 0.099346154 | V26: =O26 -> 1.2 | W26: =IF(AND($D$10="D",$C$14>=0.2),IF(V26<$F$15,IF($I$15>0.6,MAX(0.044*$C$13*$D$21,0.5*$I$15/($D$20/$D$21),1.5*$C$14/V26/($D$20/$D$21)),MAX(0.044*$C$13*$D$21,1.5*$C$14/V26/($D$20/$D$21))),IF($I$15>0.6,MAX(0.044*$C$13*$D$21,0.5*$I$15/($D$20/$D$21),1.5*$C$14*$F$15/V26^2/($D$20/$D$21)),MAX(0.044*$C$13*$D$21,1.5*$C$14*$F$15/V26^2/($D$20/$D$21)))),IF(V26<$F$15,IF($I$15>0.6,MAX(0.044*$C$13*$D$21,0.5*$I$15/($D$20/$D$21),$C$14/V26/($D$20/$D$21)),MAX(0.044*$C$13*$D$21,$C$14/V26/($D$20/$D$21))),IF($I$15>0.6,MAX(0.044*$C$13*$D$21,0.5*$I$15/($D$20/$D$21),$C$14*$F$15/V26^2/($D$20/$D$21)),MAX(0.044*$C$13*$D$21,$C$14*$F$15/V26^2/($D$20/$D$21))))) -> 0.099346154
C27: or Cs = | D27: =C14 * F15 / I13^2 / D22 -> 0.96153555 | F27: { Cs = SD1 * TL / T2 / (R / Ie) per Eq. 12.8-4 } | O27: =+O26+0.1 -> 1.3 | P27: =IF(AND($D$10="D",$C$14>=0.2),'Site Ground Motions'!O25,'Site Ground Motions'!M25) -> 0.59607692 | Q27: =P27 / $D$22 -> 0.091704142 | V27: =O27 -> 1.3 | W27: =IF(AND($D$10="D",$C$14>=0.2),IF(V27<$F$15,IF($I$15>0.6,MAX(0.044*$C$13*$D$21,0.5*$I$15/($D$20/$D$21),1.5*$C$14/V27/($D$20/$D$21)),MAX(0.044*$C$13*$D$21,1.5*$C$14/V27/($D$20/$D$21))),IF($I$15>0.6,MAX(0.044*$C$13*$D$21,0.5*$I$15/($D$20/$D$21),1.5*$C$14*$F$15/V27^2/($D$20/$D$21)),MAX(0.044*$C$13*$D$21,1.5*$C$14*$F$15/V27^2/($D$20/$D$21)))),IF(V27<$F$15,IF($I$15>0.6,MAX(0.044*$C$13*$D$21,0.5*$I$15/($D$20/$D$21),$C$14/V27/($D$20/$D$21)),MAX(0.044*$C$13*$D$21,$C$14/V27/($D$20/$D$21))),IF($I$15>0.6,MAX(0.044*$C$13*$D$21,0.5*$I$15/($D$20/$D$21),$C$14*$F$15/V27^2/($D$20/$D$21)),MAX(0.044*$C$13*$D$21,$C$14*$F$15/V27^2/($D$20/$D$21))))) -> 0.091704142
C28: or Cs = | D28: =1.5*C14 * F15 / I13^2 / D22 -> 1.4423033 | F28: { Cs = 1.5 * SD1 * TL / T2 / (R / Ie) per Eq. 12.8-4 and 11.4.8 } | O28: =+O27+0.1 -> 1.4 | P28: =IF(AND($D$10="D",$C$14>=0.2),'Site Ground Motions'!O26,'Site Ground Motions'!M26) -> 0.5535 | Q28: =P28 / $D$22 -> 0.085153846 | V28: =O28 -> 1.4 | W28: =IF(AND($D$10="D",$C$14>=0.2),IF(V28<$F$15,IF($I$15>0.6,MAX(0.044*$C$13*$D$21,0.5*$I$15/($D$20/$D$21),1.5*$C$14/V28/($D$20/$D$21)),MAX(0.044*$C$13*$D$21,1.5*$C$14/V28/($D$20/$D$21))),IF($I$15>0.6,MAX(0.044*$C$13*$D$21,0.5*$I$15/($D$20/$D$21),1.5*$C$14*$F$15/V28^2/($D$20/$D$21)),MAX(0.044*$C$13*$D$21,1.5*$C$14*$F$15/V28^2/($D$20/$D$21)))),IF(V28<$F$15,IF($I$15>0.6,MAX(0.044*$C$13*$D$21,0.5*$I$15/($D$20/$D$21),$C$14/V28/($D$20/$D$21)),MAX(0.044*$C$13*$D$21,$C$14/V28/($D$20/$D$21))),IF($I$15>0.6,MAX(0.044*$C$13*$D$21,0.5*$I$15/($D$20/$D$21),$C$14*$F$15/V28^2/($D$20/$D$21)),MAX(0.044*$C$13*$D$21,$C$14*$F$15/V28^2/($D$20/$D$21))))) -> 0.085153846
C29: or Cs = | D29: =MAX(0.01,0.044 * C13 * D21) -> 0.029796577 | F29: { Cs = 0.044 SDS Ie or 0.01 Minimum per Eq. 12.8-5 } | O29: =+O28+0.1 -> 1.5 | P29: =IF(AND($D$10="D",$C$14>=0.2),'Site Ground Motions'!O27,'Site Ground Motions'!M27) -> 0.5166 | Q29: =P29 / $D$22 -> 0.079476923 | V29: =O29 -> 1.5 | W29: =IF(AND($D$10="D",$C$14>=0.2),IF(V29<$F$15,IF($I$15>0.6,MAX(0.044*$C$13*$D$21,0.5*$I$15/($D$20/$D$21),1.5*$C$14/V29/($D$20/$D$21)),MAX(0.044*$C$13*$D$21,1.5*$C$14/V29/($D$20/$D$21))),IF($I$15>0.6,MAX(0.044*$C$13*$D$21,0.5*$I$15/($D$20/$D$21),1.5*$C$14*$F$15/V29^2/($D$20/$D$21)),MAX(0.044*$C$13*$D$21,1.5*$C$14*$F$15/V29^2/($D$20/$D$21)))),IF(V29<$F$15,IF($I$15>0.6,MAX(0.044*$C$13*$D$21,0.5*$I$15/($D$20/$D$21),$C$14/V29/($D$20/$D$21)),MAX(0.044*$C$13*$D$21,$C$14/V29/($D$20/$D$21))),IF($I$15>0.6,MAX(0.044*$C$13*$D$21,0.5*$I$15/($D$20/$D$21),$C$14*$F$15/V29^2/($D$20/$D$21)),MAX(0.044*$C$13*$D$21,$C$14*$F$15/V29^2/($D$20/$D$21))))) -> 0.079476923
C30: or Cs = | D30: =IF(I15 < 0.6, "n/a", 0.5 * 'Site Ground Motions'!C13 / D22) -> n/a | F30: { Cs = 0.5 S1 / (R / Ie) Minimum, IFF S1 > 0.6g per Eq. 12.8-6 } | O30: =+O29+0.1 -> 1.6 | P30: =IF(AND($D$10="D",$C$14>=0.2),'Site Ground Motions'!O28,'Site Ground Motions'!M28) -> 0.4843125 | Q30: =P30 / $D$22 -> 0.074509615 | V30: =O30 -> 1.6 | W30: =IF(AND($D$10="D",$C$14>=0.2),IF(V30<$F$15,IF($I$15>0.6,MAX(0.044*$C$13*$D$21,0.5*$I$15/($D$20/$D$21),1.5*$C$14/V30/($D$20/$D$21)),MAX(0.044*$C$13*$D$21,1.5*$C$14/V30/($D$20/$D$21))),IF($I$15>0.6,MAX(0.044*$C$13*$D$21,0.5*$I$15/($D$20/$D$21),1.5*$C$14*$F$15/V30^2/($D$20/$D$21)),MAX(0.044*$C$13*$D$21,1.5*$C$14*$F$15/V30^2/($D$20/$D$21)))),IF(V30<$F$15,IF($I$15>0.6,MAX(0.044*$C$13*$D$21,0.5*$I$15/($D$20/$D$21),$C$14/V30/($D$20/$D$21)),MAX(0.044*$C$13*$D$21,$C$14/V30/($D$20/$D$21))),IF($I$15>0.6,MAX(0.044*$C$13*$D$21,0.5*$I$15/($D$20/$D$21),$C$14*$F$15/V30^2/($D$20/$D$21)),MAX(0.044*$C$13*$D$21,$C$14*$F$15/V30^2/($D$20/$D$21))))) -> 0.074509615
O31: =+O30+0.1 -> 1.7 | P31: =IF(AND($D$10="D",$C$14>=0.2),'Site Ground Motions'!O29,'Site Ground Motions'!M29) -> 0.45582353 | Q31: =P31 / $D$22 -> 0.070126697 | V31: =O31 -> 1.7 | W31: =IF(AND($D$10="D",$C$14>=0.2),IF(V31<$F$15,IF($I$15>0.6,MAX(0.044*$C$13*$D$21,0.5*$I$15/($D$20/$D$21),1.5*$C$14/V31/($D$20/$D$21)),MAX(0.044*$C$13*$D$21,1.5*$C$14/V31/($D$20/$D$21))),IF($I$15>0.6,MAX(0.044*$C$13*$D$21,0.5*$I$15/($D$20/$D$21),1.5*$C$14*$F$15/V31^2/($D$20/$D$21)),MAX(0.044*$C$13*$D$21,1.5*$C$14*$F$15/V31^2/($D$20/$D$21)))),IF(V31<$F$15,IF($I$15>0.6,MAX(0.044*$C$13*$D$21,0.5*$I$15/($D$20/$D$21),$C$14/V31/($D$20/$D$21)),MAX(0.044*$C$13*$D$21,$C$14/V31/($D$20/$D$21))),IF($I$15>0.6,MAX(0.044*$C$13*$D$21,0.5*$I$15/($D$20/$D$21),$C$14*$F$15/V31^2/($D$20/$D$21)),MAX(0.044*$C$13*$D$21,$C$14*$F$15/V31^2/($D$20/$D$21))))) -> 0.070126697
C32: USE Cs = | D32: =O17 -> 0.10366555 | F32: V = | G32: =D32 -> 0.10366555 | O32: =+O31+0.1 -> 1.8 | P32: =IF(AND($D$10="D",$C$14>=0.2),'Site Ground Motions'!O30,'Site Ground Motions'!M30) -> 0.4305 | Q32: =P32 / $D$22 -> 0.066230769 | V32: =O32 -> 1.8 | W32: =IF(AND($D$10="D",$C$14>=0.2),IF(V32<$F$15,IF($I$15>0.6,MAX(0.044*$C$13*$D$21,0.5*$I$15/($D$20/$D$21),1.5*$C$14/V32/($D$20/$D$21)),MAX(0.044*$C$13*$D$21,1.5*$C$14/V32/($D$20/$D$21))),IF($I$15>0.6,MAX(0.044*$C$13*$D$21,0.5*$I$15/($D$20/$D$21),1.5*$C$14*$F$15/V32^2/($D$20/$D$21)),MAX(0.044*$C$13*$D$21,1.5*$C$14*$F$15/V32^2/($D$20/$D$21)))),IF(V32<$F$15,IF($I$15>0.6,MAX(0.044*$C$13*$D$21,0.5*$I$15/($D$20/$D$21),$C$14/V32/($D$20/$D$21)),MAX(0.044*$C$13*$D$21,$C$14/V32/($D$20/$D$21))),IF($I$15>0.6,MAX(0.044*$C$13*$D$21,0.5*$I$15/($D$20/$D$21),$C$14*$F$15/V32^2/($D$20/$D$21)),MAX(0.044*$C$13*$D$21,$C$14*$F$15/V32^2/($D$20/$D$21))))) -> 0.066230769
O33: =+O32+0.1 -> 1.9 | P33: =IF(AND($D$10="D",$C$14>=0.2),'Site Ground Motions'!O31,'Site Ground Motions'!M31) -> 0.40784211 | Q33: =P33 / $D$22 -> 0.062744939 | V33: =O33 -> 1.9 | W33: =IF(AND($D$10="D",$C$14>=0.2),IF(V33<$F$15,IF($I$15>0.6,MAX(0.044*$C$13*$D$21,0.5*$I$15/($D$20/$D$21),1.5*$C$14/V33/($D$20/$D$21)),MAX(0.044*$C$13*$D$21,1.5*$C$14/V33/($D$20/$D$21))),IF($I$15>0.6,MAX(0.044*$C$13*$D$21,0.5*$I$15/($D$20/$D$21),1.5*$C$14*$F$15/V33^2/($D$20/$D$21)),MAX(0.044*$C$13*$D$21,1.5*$C$14*$F$15/V33^2/($D$20/$D$21)))),IF(V33<$F$15,IF($I$15>0.6,MAX(0.044*$C$13*$D$21,0.5*$I$15/($D$20/$D$21),$C$14/V33/($D$20/$D$21)),MAX(0.044*$C$13*$D$21,$C$14/V33/($D$20/$D$21))),IF($I$15>0.6,MAX(0.044*$C$13*$D$21,0.5*$I$15/($D$20/$D$21),$C$14*$F$15/V33^2/($D$20/$D$21)),MAX(0.044*$C$13*$D$21,$C$14*$F$15/V33^2/($D$20/$D$21))))) -> 0.062744939
O34: =+O33+0.1 -> 2 | P34: =IF(AND($D$10="D",$C$14>=0.2),'Site Ground Motions'!O32,'Site Ground Motions'!M32) -> 0.38745 | Q34: =P34 / $D$22 -> 0.059607692 | V34: =O34 -> 2 | W34: =IF(AND($D$10="D",$C$14>=0.2),IF(V34<$F$15,IF($I$15>0.6,MAX(0.044*$C$13*$D$21,0.5*$I$15/($D$20/$D$21),1.5*$C$14/V34/($D$20/$D$21)),MAX(0.044*$C$13*$D$21,1.5*$C$14/V34/($D$20/$D$21))),IF($I$15>0.6,MAX(0.044*$C$13*$D$21,0.5*$I$15/($D$20/$D$21),1.5*$C$14*$F$15/V34^2/($D$20/$D$21)),MAX(0.044*$C$13*$D$21,1.5*$C$14*$F$15/V34^2/($D$20/$D$21)))),IF(V34<$F$15,IF($I$15>0.6,MAX(0.044*$C$13*$D$21,0.5*$I$15/($D$20/$D$21),$C$14/V34/($D$20/$D$21)),MAX(0.044*$C$13*$D$21,$C$14/V34/($D$20/$D$21))),IF($I$15>0.6,MAX(0.044*$C$13*$D$21,0.5*$I$15/($D$20/$D$21),$C$14*$F$15/V34^2/($D$20/$D$21)),MAX(0.044*$C$13*$D$21,$C$14*$F$15/V34^2/($D$20/$D$21))))) -> 0.059607692
O35: =+O34+0.1 -> 2.1 | P35: =IF(AND($D$10="D",$C$14>=0.2),'Site Ground Motions'!O33,'Site Ground Motions'!M33) -> 0.369 | Q35: =P35 / $D$22 -> 0.056769231 | V35: =O35 -> 2.1 | W35: =IF(AND($D$10="D",$C$14>=0.2),IF(V35<$F$15,IF($I$15>0.6,MAX(0.044*$C$13*$D$21,0.5*$I$15/($D$20/$D$21),1.5*$C$14/V35/($D$20/$D$21)),MAX(0.044*$C$13*$D$21,1.5*$C$14/V35/($D$20/$D$21))),IF($I$15>0.6,MAX(0.044*$C$13*$D$21,0.5*$I$15/($D$20/$D$21),1.5*$C$14*$F$15/V35^2/($D$20/$D$21)),MAX(0.044*$C$13*$D$21,1.5*$C$14*$F$15/V35^2/($D$20/$D$21)))),IF(V35<$F$15,IF($I$15>0.6,MAX(0.044*$C$13*$D$21,0.5*$I$15/($D$20/$D$21),$C$14/V35/($D$20/$D$21)),MAX(0.044*$C$13*$D$21,$C$14/V35/($D$20/$D$21))),IF($I$15>0.6,MAX(0.044*$C$13*$D$21,0.5*$I$15/($D$20/$D$21),$C$14*$F$15/V35^2/($D$20/$D$21)),MAX(0.044*$C$13*$D$21,$C$14*$F$15/V35^2/($D$20/$D$21))))) -> 0.056769231
O36: =+O35+0.1 -> 2.2 | P36: =IF(AND($D$10="D",$C$14>=0.2),'Site Ground Motions'!O34,'Site Ground Motions'!M34) -> 0.35222727 | Q36: =P36 / $D$22 -> 0.054188811 | V36: =O36 -> 2.2 | W36: =IF(AND($D$10="D",$C$14>=0.2),IF(V36<$F$15,IF($I$15>0.6,MAX(0.044*$C$13*$D$21,0.5*$I$15/($D$20/$D$21),1.5*$C$14/V36/($D$20/$D$21)),MAX(0.044*$C$13*$D$21,1.5*$C$14/V36/($D$20/$D$21))),IF($I$15>0.6,MAX(0.044*$C$13*$D$21,0.5*$I$15/($D$20/$D$21),1.5*$C$14*$F$15/V36^2/($D$20/$D$21)),MAX(0.044*$C$13*$D$21,1.5*$C$14*$F$15/V36^2/($D$20/$D$21)))),IF(V36<$F$15,IF($I$15>0.6,MAX(0.044*$C$13*$D$21,0.5*$I$15/($D$20/$D$21),$C$14/V36/($D$20/$D$21)),MAX(0.044*$C$13*$D$21,$C$14/V36/($D$20/$D$21))),IF($I$15>0.6,MAX(0.044*$C$13*$D$21,0.5*$I$15/($D$20/$D$21),$C$14*$F$15/V36^2/($D$20/$D$21)),MAX(0.044*$C$13*$D$21,$C$14*$F$15/V36^2/($D$20/$D$21))))) -> 0.054188811
O37: =+O36+0.1 -> 2.3 | P37: =IF(AND($D$10="D",$C$14>=0.2),'Site Ground Motions'!O35,'Site Ground Motions'!M35) -> 0.33691304 | Q37: =P37 / $D$22 -> 0.051832776 | V37: =O37 -> 2.3 | W37: =IF(AND($D$10="D",$C$14>=0.2),IF(V37<$F$15,IF($I$15>0.6,MAX(0.044*$C$13*$D$21,0.5*$I$15/($D$20/$D$21),1.5*$C$14/V37/($D$20/$D$21)),MAX(0.044*$C$13*$D$21,1.5*$C$14/V37/($D$20/$D$21))),IF($I$15>0.6,MAX(0.044*$C$13*$D$21,0.5*$I$15/($D$20/$D$21),1.5*$C$14*$F$15/V37^2/($D$20/$D$21)),MAX(0.044*$C$13*$D$21,1.5*$C$14*$F$15/V37^2/($D$20/$D$21)))),IF(V37<$F$15,IF($I$15>0.6,MAX(0.044*$C$13*$D$21,0.5*$I$15/($D$20/$D$21),$C$14/V37/($D$20/$D$21)),MAX(0.044*$C$13*$D$21,$C$14/V37/($D$20/$D$21))),IF($I$15>0.6,MAX(0.044*$C$13*$D$21,0.5*$I$15/($D$20/$D$21),$C$14*$F$15/V37^2/($D$20/$D$21)),MAX(0.044*$C$13*$D$21,$C$14*$F$15/V37^2/($D$20/$D$21))))) -> 0.051832776
O38: =+O37+0.1 -> 2.4 | P38: =IF(AND($D$10="D",$C$14>=0.2),'Site Ground Motions'!O36,'Site Ground Motions'!M36) -> 0.322875 | Q38: =P38 / $D$22 -> 0.049673077 | V38: =O38 -> 2.4 | W38: =IF(AND($D$10="D",$C$14>=0.2),IF(V38<$F$15,IF($I$15>0.6,MAX(0.044*$C$13*$D$21,0.5*$I$15/($D$20/$D$21),1.5*$C$14/V38/($D$20/$D$21)),MAX(0.044*$C$13*$D$21,1.5*$C$14/V38/($D$20/$D$21))),IF($I$15>0.6,MAX(0.044*$C$13*$D$21,0.5*$I$15/($D$20/$D$21),1.5*$C$14*$F$15/V38^2/($D$20/$D$21)),MAX(0.044*$C$13*$D$21,1.5*$C$14*$F$15/V38^2/($D$20/$D$21)))),IF(V38<$F$15,IF($I$15>0.6,MAX(0.044*$C$13*$D$21,0.5*$I$15/($D$20/$D$21),$C$14/V38/($D$20/$D$21)),MAX(0.044*$C$13*$D$21,$C$14/V38/($D$20/$D$21))),IF($I$15>0.6,MAX(0.044*$C$13*$D$21,0.5*$I$15/($D$20/$D$21),$C$14*$F$15/V38^2/($D$20/$D$21)),MAX(0.044*$C$13*$D$21,$C$14*$F$15/V38^2/($D$20/$D$21))))) -> 0.049673077
O39: =+O38+0.1 -> 2.5 | P39: =IF(AND($D$10="D",$C$14>=0.2),'Site Ground Motions'!O37,'Site Ground Motions'!M37) -> 0.30996 | Q39: =P39 / $D$22 -> 0.047686154 | V39: =O39 -> 2.5 | W39: =IF(AND($D$10="D",$C$14>=0.2),IF(V39<$F$15,IF($I$15>0.6,MAX(0.044*$C$13*$D$21,0.5*$I$15/($D$20/$D$21),1.5*$C$14/V39/($D$20/$D$21)),MAX(0.044*$C$13*$D$21,1.5*$C$14/V39/($D$20/$D$21))),IF($I$15>0.6,MAX(0.044*$C$13*$D$21,0.5*$I$15/($D$20/$D$21),1.5*$C$14*$F$15/V39^2/($D$20/$D$21)),MAX(0.044*$C$13*$D$21,1.5*$C$14*$F$15/V39^2/($D$20/$D$21)))),IF(V39<$F$15,IF($I$15>0.6,MAX(0.044*$C$13*$D$21,0.5*$I$15/($D$20/$D$21),$C$14/V39/($D$20/$D$21)),MAX(0.044*$C$13*$D$21,$C$14/V39/($D$20/$D$21))),IF($I$15>0.6,MAX(0.044*$C$13*$D$21,0.5*$I$15/($D$20/$D$21),$C$14*$F$15/V39^2/($D$20/$D$21)),MAX(0.044*$C$13*$D$21,$C$14*$F$15/V39^2/($D$20/$D$21))))) -> 0.047686154
O40: =+O39+0.1 -> 2.6 | P40: =IF(AND($D$10="D",$C$14>=0.2),'Site Ground Motions'!O38,'Site Ground Motions'!M38) -> 0.29803846 | Q40: =P40 / $D$22 -> 0.045852071 | V40: =O40 -> 2.6 | W40: =IF(AND($D$10="D",$C$14>=0.2),IF(V40<$F$15,IF($I$15>0.6,MAX(0.044*$C$13*$D$21,0.5*$I$15/($D$20/$D$21),1.5*$C$14/V40/($D$20/$D$21)),MAX(0.044*$C$13*$D$21,1.5*$C$14/V40/($D$20/$D$21))),IF($I$15>0.6,MAX(0.044*$C$13*$D$21,0.5*$I$15/($D$20/$D$21),1.5*$C$14*$F$15/V40^2/($D$20/$D$21)),MAX(0.044*$C$13*$D$21,1.5*$C$14*$F$15/V40^2/($D$20/$D$21)))),IF(V40<$F$15,IF($I$15>0.6,MAX(0.044*$C$13*$D$21,0.5*$I$15/($D$20/$D$21),$C$14/V40/($D$20/$D$21)),MAX(0.044*$C$13*$D$21,$C$14/V40/($D$20/$D$21))),IF($I$15>0.6,MAX(0.044*$C$13*$D$21,0.5*$I$15/($D$20/$D$21),$C$14*$F$15/V40^2/($D$20/$D$21)),MAX(0.044*$C$13*$D$21,$C$14*$F$15/V40^2/($D$20/$D$21))))) -> 0.045852071
O41: =+O40+0.1 -> 2.7 | P41: =IF(AND($D$10="D",$C$14>=0.2),'Site Ground Motions'!O39,'Site Ground Motions'!M39) -> 0.287 | Q41: =P41 / $D$22 -> 0.044153846 | V41: =O41 -> 2.7 | W41: =IF(AND($D$10="D",$C$14>=0.2),IF(V41<$F$15,IF($I$15>0.6,MAX(0.044*$C$13*$D$21,0.5*$I$15/($D$20/$D$21),1.5*$C$14/V41/($D$20/$D$21)),MAX(0.044*$C$13*$D$21,1.5*$C$14/V41/($D$20/$D$21))),IF($I$15>0.6,MAX(0.044*$C$13*$D$21,0.5*$I$15/($D$20/$D$21),1.5*$C$14*$F$15/V41^2/($D$20/$D$21)),MAX(0.044*$C$13*$D$21,1.5*$C$14*$F$15/V41^2/($D$20/$D$21)))),IF(V41<$F$15,IF($I$15>0.6,MAX(0.044*$C$13*$D$21,0.5*$I$15/($D$20/$D$21),$C$14/V41/($D$20/$D$21)),MAX(0.044*$C$13*$D$21,$C$14/V41/($D$20/$D$21))),IF($I$15>0.6,MAX(0.044*$C$13*$D$21,0.5*$I$15/($D$20/$D$21),$C$14*$F$15/V41^2/($D$20/$D$21)),MAX(0.044*$C$13*$D$21,$C$14*$F$15/V41^2/($D$20/$D$21))))) -> 0.044153846
O42: =+O41+0.1 -> 2.8 | P42: =IF(AND($D$10="D",$C$14>=0.2),'Site Ground Motions'!O40,'Site Ground Motions'!M40) -> 0.2672069 | Q42: =P42 / $D$22 -> 0.041108753 | V42: =O42 -> 2.8 | W42: =IF(AND($D$10="D",$C$14>=0.2),IF(V42<$F$15,IF($I$15>0.6,MAX(0.044*$C$13*$D$21,0.5*$I$15/($D$20/$D$21),1.5*$C$14/V42/($D$20/$D$21)),MAX(0.044*$C$13*$D$21,1.5*$C$14/V42/($D$20/$D$21))),IF($I$15>0.6,MAX(0.044*$C$13*$D$21,0.5*$I$15/($D$20/$D$21),1.5*$C$14*$F$15/V42^2/($D$20/$D$21)),MAX(0.044*$C$13*$D$21,1.5*$C$14*$F$15/V42^2/($D$20/$D$21)))),IF(V42<$F$15,IF($I$15>0.6,MAX(0.044*$C$13*$D$21,0.5*$I$15/($D$20/$D$21),$C$14/V42/($D$20/$D$21)),MAX(0.044*$C$13*$D$21,$C$14/V42/($D$20/$D$21))),IF($I$15>0.6,MAX(0.044*$C$13*$D$21,0.5*$I$15/($D$20/$D$21),$C$14*$F$15/V42^2/($D$20/$D$21)),MAX(0.044*$C$13*$D$21,$C$14*$F$15/V42^2/($D$20/$D$21))))) -> 0.042576923
...

Sheet Vertical Distribution
E1: Project: | F1: =+IF('Site Ground Motions'!E1="","",'Site Ground Motions'!E1) | K1: By: | L1: =+IF('Site Ground Motions'!I1="","",'Site Ground Motions'!I1) | M1: Sheet No. | O1: GRAY AREA USED FOR NOTES TO ENGINEER OR BACK-UP CALCS (DOES NOT PRINT) | W1: Template version: | X1: ='Site Ground Motions'!X1 -> 2.1
E2: Location: | F2: =+IF('Site Ground Motions'!E2="","",'Site Ground Motions'!E2) | K2: Date: | L2: =+IF('Site Ground Motions'!I2="","",'Site Ground Motions'!I2) | M2: 4 OF 5 | O2: * NOTE: TITLEBLOCK INFORMATION REFERENCES "SITE GROUND MOTION" PAGE | W2: Last updated: | X2: ='Site Ground Motions'!X2 -> 45201
E3: Client: | F3: =+IF('Site Ground Motions'!E3="","",'Site Ground Motions'!E3) | K3: Revised: | L3: =+IF('Site Ground Motions'!I3="","",'Site Ground Motions'!I3) | M3: Job No.
E4: Subject: | F4: VERTICAL DISTRIBUTION | K4: Date: | L4: =+IF('Site Ground Motions'!I4="","",'Site Ground Motions'!I4) | M4: =+IF('Site Ground Motions'!J4="","",'Site Ground Motions'!J4)
B5: Vertical Distribution of Lateral Forces Per ASCE 7-16 Section 12.8.3
O6: FORMATTING LEGEND
P7: Blank highlighted cell = requires engineer input to run.
D8: Building Period = | E8: =+'Site Ground Motions'!C33 -> 1.15 | G8: k = | H8: =IF(E8 < 0.5, 1, IF(E8 > 2.5, 2, 0.5 * E8 + 0.75)) -> 1.325 | I8: Per ASCE 7-16 12.8.3 | O8: 888 | P8: Shaded cell = value requires engineer review/input.
D9: Building Weight = | E9: =F18 -> 2022 | O9: 1.05 | P9: Bold red indicates design warning.
D11: # Stories = | E11: 4 | H11: Base Shear, V = | I11: ='Equivalent Lateral Forces'!D32 -> 0.10366555 | O11: Up to 12 stories supported by default. Formulas can be extended to additional levels as required.
D12: Ground Elevation= | E12: 0 | H12: Base Shear, V = | I12: =I11 * E9 -> 209.61175
C15: VERTICAL DISTRIBUTION
D16: Building | F16: Bldg. Wt.
D17: Height | F17: Swx | G17: Swxhxk | H17: SCvx | I17: SFx
D18: =SUM(D25:D36) -> 42.5 | F18: =SUM(F24:F36) -> 2022 | G18: =SUM(G24:G36) -> 154062.74 | H18: =SUM(H24:H36) -> 1 | I18: =SUM(I24:I36) -> 209.61175
E20: Lateral Force Acts at a Height of: | F20: =MAX(K25:K32) / I12 -> 31.5664 | G20: which equals | I20: =F20 / D18 -> 0.74273882 | J20: of Building Height
D22: Floor | E22: Elevation | F22: Floor Wt.
C23: Level | D23: Height | E23: hx | F23: wx | G23: wxhxk | H23: Cvx | I23: Fx | J23: Vx | K23: OTM
C24: Roof | D24: — | E24: =SUM(D25:D36)+E12 -> 42.5 | F24: 352 | G24: =F24 * (E24-E$12)^$H$8 -> 50600.871 | H24: =G24 / $G$18 -> 0.32844328 | I24: =H24 * $I$12 -> 68.845568 | J24: — | K24: — | P24: Vertical Distribution Story Table Range
C25: =E11 -> 4 | D25: 10 | E25: =IF(C25<>"",E24-D25,"") -> 32.5 | F25: 554 | G25: =IF(C25="","",IF(C25="Ground","—",F25 * (E25-E$12)^$H$8)) -> 55815.551 | H25: =IF(C25="","",IF(C25="Ground","—",G25 / $G$18)) -> 0.36229104 | I25: =IF(C25="","",IF(C25="Ground","—",H25 * $I$12)) -> 75.940458 | J25: =IF(C25="","",IF(C25="Ground","—",I24)) -> 68.845568 | K25: =IF(C25="","",J25 * D25) -> 688.45568 | O25: counter
C26: =IF(E$11-O26>1,E$11-O26,IF(E$11-O26=1,"Ground","")) -> 3 | D26: 10.5 | E26: =IF(C26<>"",E25-D26,"") -> 22 | F26: 556 | G26: =IF(C26="","",IF(C26="Ground","—",F26 * (E26-E$12)^$H$8)) -> 33402.952 | H26: =IF(C26="","",IF(C26="Ground","—",G26 / $G$18)) -> 0.21681395 | I26: =IF(C26="","",IF(C26="Ground","—",H26 * $I$12)) -> 45.446751 | J26: =IF(C26="","",I25+J25) -> 144.78603 | K26: =IF(C26="","",J26 * D26+K25) -> 2208.709 | O26: 1
C27: =IF(E$11-O27>1,E$11-O27,IF(E$11-O27=1,"Ground","")) -> 2 | D27: 10.5 | E27: =IF(C27<>"",E26-D27,"") -> 11.5 | F27: 560 | G27: =IF(C27="","",IF(C27="Ground","—",F27 * (E27-E$12)^$H$8)) -> 14243.367 | H27: =IF(C27="","",IF(C27="Ground","—",G27 / $G$18)) -> 0.09245173 | I27: =IF(C27="","",IF(C27="Ground","—",H27 * $I$12)) -> 19.378969 | J27: =IF(C27="","",I26+J26) -> 190.23278 | K27: =IF(C27="","",J27 * D27+K26) -> 4206.1531 | O27: 2
C28: =IF(E$11-O28>1,E$11-O28,IF(E$11-O28=1,"Ground","")) -> Ground | D28: 11.5 | E28: =IF(C28<>"",E27-D28,"") -> 0 | G28: =IF(C28="","",IF(C28="Ground","—",F28 * (E28-E$12)^$H$8)) -> — | H28: =IF(C28="","",IF(C28="Ground","—",G28 / $G$18)) -> — | I28: =IF(C28="","",IF(C28="Ground","—",H28 * $I$12)) -> — | J28: =IF(C28="","",I27+J27) -> 209.61175 | K28: =IF(C28="","",J28 * D28+K27) -> 6616.6882 | O28: 3
C29: =IF(E$11-O29>1,E$11-O29,IF(E$11-O29=1,"Ground","")) | E29: =IF(C29<>"",E28-D29,"") | G29: =IF(C29="","",IF(C29="Ground","—",F29 * (E29-E$12)^$H$8)) | H29: =IF(C29="","",IF(C29="Ground","—",G29 / $G$18)) | I29: =IF(C29="","",IF(C29="Ground","—",H29 * $I$12)) | J29: =IF(C29="","",I28+J28) | K29: =IF(C29="","",J29 * D29+K28) | O29: 4
C30: =IF(E$11-O30>1,E$11-O30,IF(E$11-O30=1,"Ground","")) | E30: =IF(C30<>"",E29-D30,"") | G30: =IF(C30="","",IF(C30="Ground","—",F30 * (E30-E$12)^$H$8)) | H30: =IF(C30="","",IF(C30="Ground","—",G30 / $G$18)) | I30: =IF(C30="","",IF(C30="Ground","—",H30 * $I$12)) | J30: =IF(C30="","",I29+J29) | K30: =IF(C30="","",J30 * D30+K29) | O30: 5
C31: =IF(E$11-O31>1,E$11-O31,IF(E$11-O31=1,"Ground","")) | E31: =IF(C31<>"",E30-D31,"") | G31: =IF(C31="","",IF(C31="Ground","—",F31 * (E31-E$12)^$H$8)) | H31: =IF(C31="","",IF(C31="Ground","—",G31 / $G$18)) | I31: =IF(C31="","",IF(C31="Ground","—",H31 * $I$12)) | J31: =IF(C31="","",I30+J30) | K31: =IF(C31="","",J31 * D31+K30) | O31: 6
C32: =IF(E$11-O32>1,E$11-O32,IF(E$11-O32=1,"Ground","")) | E32: =IF(C32<>"",E31-D32,"") | G32: =IF(C32="","",IF(C32="Ground","—",F32 * (E32-E$12)^$H$8)) | H32: =IF(C32="","",IF(C32="Ground","—",G32 / $G$18)) | I32: =IF(C32="","",IF(C32="Ground","—",H32 * $I$12)) | J32: =IF(C32="","",I31+J31) | K32: =IF(C32="","",J32 * D32+K31) | O32: 7
C33: =IF(E$11-O33>1,E$11-O33,IF(E$11-O33=1,"Ground","")) | E33: =IF(C33<>"",E32-D33,"") | G33: =IF(C33="","",IF(C33="Ground","—",F33 * (E33-E$12)^$H$8)) | H33: =IF(C33="","",IF(C33="Ground","—",G33 / $G$18)) | I33: =IF(C33="","",IF(C33="Ground","—",H33 * $I$12)) | J33: =IF(C33="","",I32+J32) | K33: =IF(C33="","",J33 * D33+K32) | O33: 8
C34: =IF(E$11-O34>1,E$11-O34,IF(E$11-O34=1,"Ground","")) | E34: =IF(C34<>"",E33-D34,"") | G34: =IF(C34="","",IF(C34="Ground","—",F34 * (E34-E$12)^$H$8)) | H34: =IF(C34="","",IF(C34="Ground","—",G34 / $G$18)) | I34: =IF(C34="","",IF(C34="Ground","—",H34 * $I$12)) | J34: =IF(C34="","",I33+J33) | K34: =IF(C34="","",J34 * D34+K33) | O34: 9
C35: =IF(E$11-O35>1,E$11-O35,IF(E$11-O35=1,"Ground","")) | E35: =IF(C35<>"",E34-D35,"") | G35: =IF(C35="","",IF(C35="Ground","—",F35 * (E35-E$12)^$H$8)) | H35: =IF(C35="","",IF(C35="Ground","—",G35 / $G$18)) | I35: =IF(C35="","",IF(C35="Ground","—",H35 * $I$12)) | J35: =IF(C35="","",I34+J34) | K35: =IF(C35="","",J35 * D35+K34) | O35: 10
C36: =IF(E$11-O36>1,E$11-O36,IF(E$11-O36=1,"Ground","")) | E36: =IF(C36<>"",E35-D36,"") | G36: =IF(C36="","",IF(C36="Ground","—",F36 * (E36-E$12)^$H$8)) | H36: =IF(C36="","",IF(C36="Ground","—",G36 / $G$18)) | I36: =IF(C36="","",IF(C36="Ground","—",H36 * $I$12)) | J36: =IF(C36="","",I35+J35) | K36: =IF(C36="","",J36 * D36+K35) | O36: 11
C38: ANALYSIS MODEL VALIDATION | O38: Where a lateral analysis model (such as ETABS) is used for Equivalent Lateral Force (ELF) or Linear Dynamic Analysis, use this section.
O39: Hide or delete for other projects.
D40: ETABS | I40: ETABS | O40: In ETABS, see Tables -> Other Definitions -> Mass Data -> Table: Mass Summary by Story
D41: MASS BY STORY | F41: TAKEOFF | I41: FORCE BY STORY | K41: TAKEOFF | O41: In ETABS, see Tables -> Analysis Results -> Structure Output -> Other Output Items -> Table: Story Forces
C42: Level | D42: lb-s^2/ft | E42: k | F42: wx | G42: % Δ | I42: VX, K | J42: VY, K | K42: Fx | L42: X - % Δ | M42: Y - % Δ
C43: Roof | E43: =IF(ISNUMBER(D43),D43*32.2/1000,"") | F43: =IF(ISNUMBER(F24),F24,"") -> 352 | G43: =IF(ISNUMBER(F43),E43/F43-1,"") -> #VALUE! | K43: =I24 -> 68.845568 | L43: =IF(ISNUMBER(K43),I43/K43-1,"") -> -1 | M43: =IF(ISNUMBER(K43),J43/K43-1,"") -> -1 | P43: Analysis Model Validation Table Range
C44: =E11 -> 4 | E44: =IF(ISNUMBER(D44),D44*32.2/1000,"") | F44: =IF(ISNUMBER(F25),F25,"") -> 554 | G44: =IF(ISNUMBER(F44),E44/F44-1,"") -> #VALUE! | K44: =I25 -> 75.940458 | L44: =IF(ISNUMBER(K44),I44/K44-1,"") -> -1 | M44: =IF(ISNUMBER(K44),J44/K44-1,"") -> -1 | O44: counter
C45: =IF(E$11-O45>1,E$11-O45,IF(E$11-O45=1,"Ground","")) -> 3 | E45: =IF(ISNUMBER(D45),D45*32.2/1000,"") | F45: =IF(ISNUMBER(F26),F26,"") -> 556 | G45: =IF(ISNUMBER(F45),E45/F45-1,"") -> #VALUE! | K45: =I26 -> 45.446751 | L45: =IF(ISNUMBER(K45),I45/K45-1,"") -> -1 | M45: =IF(ISNUMBER(K45),J45/K45-1,"") -> -1 | O45: 1
C46: =IF(E$11-O46>1,E$11-O46,IF(E$11-O46=1,"Ground","")) -> 2 | E46: =IF(ISNUMBER(D46),D46*32.2/1000,"") | F46: =IF(ISNUMBER(F27),F27,"") -> 560 | G46: =IF(ISNUMBER(F46),E46/F46-1,"") -> #VALUE! | K46: =I27 -> 19.378969 | L46: =IF(ISNUMBER(K46),I46/K46-1,"") -> -1 | M46: =IF(ISNUMBER(K46),J46/K46-1,"") -> -1 | O46: 2
...

Sheet Diaphragm Forces
C1: Project: | D1: =+IF('Site Ground Motions'!E1="","",'Site Ground Motions'!E1) | I1: By: | J1: =+IF('Site Ground Motions'!I1="","",'Site Ground Motions'!I1) | K1: Sheet No. | M1: GRAY AREA USED FOR NOTES TO ENGINEER OR BACK-UP CALCS (DOES NOT PRINT) | W1: Template version: | X1: ='Site Ground Motions'!X1 -> 2.1
C2: Location: | D2: =+IF('Site Ground Motions'!E2="","",'Site Ground Motions'!E2) | I2: Date: | J2: =+IF('Site Ground Motions'!I2="","",'Site Ground Motions'!I2) | K2: 5 of 5 | M2: * NOTE: TITLEBLOCK INFORMATION REFERENCES "SITE GROUND MOTION" PAGE | W2: Last updated: | X2: ='Site Ground Motions'!X2 -> 45201
C3: Client: | D3: =+IF('Site Ground Motions'!E3="","",'Site Ground Motions'!E3) | I3: Revised: | J3: =+IF('Site Ground Motions'!I3="","",'Site Ground Motions'!I3) | K3: Job No.
C4: Subject: | D4: DIAPHRAGM FORCES | I4: Date: | J4: =+IF('Site Ground Motions'!I4="","",'Site Ground Motions'!I4) | K4: =+IF('Site Ground Motions'!J4="","",'Site Ground Motions'!J4)
M6: FORMATTING LEGEND
A7: Diaphragm Forces per ASCE 7-16, Section 12.10 | N7: Blank highlighted cell = requires engineer input to run.
M8: 888 | N8: Shaded cell = value requires engineer review/input.
C9: Building Weight = | D9: =+'Vertical Distribution'!E9 -> 2022 | M9: 1.05 | N9: Bold red indicates design warning.
F10: Base Shear, V = | G10: =+'Vertical Distribution'!I12 -> 209.61175
B12: SDS = | C12: ='Site Ground Motions'!C21 -> 0.67719493 | E12: Ie = | F12: ='Equivalent Lateral Forces'!D21 -> 1
B14: Swx | D14: SFx
B15: =SUM(B18:B28) -> 2022 | D15: =SUM(D18:D28) -> 209.61175 | G15: Equation | H15: 12.10-2 | I15: 12.10-3
G16: 12.10-1 | H16: Min. | I16: Max.
A17: Floor | B17: wx | C17: Swx | D17: Fx | E17: SFx | F17: SFx / Swx | G17: Fpx | H17: Fpx | I17: Fpx | J17: Fpx | K17: Fpx / Wx | L17: Column to ratio Fpx to Fx?
A18: =+'Vertical Distribution'!C24 -> Roof | B18: =IF(A18="Ground","—",IF(A18="","",'Vertical Distribution'!F24)) -> 352 | C18: =B18 -> 352 | D18: =+'Vertical Distribution'!I24 -> 68.845568 | E18: =D18 -> 68.845568 | F18: =E18 / C18 -> 0.195584 | G18: =F18 * B18 -> 68.845568 | H18: =0.2 * $C$12 * $F$12 * B18 -> 47.674523 | I18: =0.4 * $C$12 * $F$12 * B18 -> 95.349047 | J18: =IF(I18 < MAX(G18, H18), I18, MAX(G18, H18)) -> 68.845568 | K18: =J18/B18 -> 0.195584 | M18: Vertical Distribution Story Table Range
A19: =+'Vertical Distribution'!C25 -> 4 | B19: =IF(A19="Ground","—",IF(A19="","",'Vertical Distribution'!F25)) -> 554 | C19: =IF(A19="Ground","—",IF(A19="","",C18 + B19)) -> 906 | D19: =IF(A19="Ground","—",IF(A19="","",'Vertical Distribution'!I25)) -> 75.940458 | E19: =IF(A19="Ground","—",IF(A19="","",E18 + D19)) -> 144.78603 | F19: =IF(A19="Ground","—",IF(A19="","",E19/C19)) -> 0.15980798 | G19: =IF(A19="Ground","—",IF(A19="","",F19*B19)) -> 88.533619 | H19: =IF(A19="Ground","—",IF(A19="","",0.2*$C$12*$F$12*B19)) -> 75.033199 | I19: =IF(A19="Ground","—",IF(A19="","",0.4*$C$12*$F$12*B19)) -> 150.0664 | J19: =IF(A19="Ground","—",IF(A19="","",IF(I19<MAX(G19,H19),I19,MAX(G19,H19)))) -> 88.533619 | K19: =IF(A19="Ground","—",IF(A19="","",J19/B19)) -> 0.15980798
A20: =+'Vertical Distribution'!C26 -> 3 | B20: =IF(A20="Ground","—",IF(A20="","",'Vertical Distribution'!F26)) -> 556 | C20: =IF(A20="Ground","—",IF(A20="","",C19 + B20)) -> 1462 | D20: =IF(A20="Ground","—",IF(A20="","",'Vertical Distribution'!I26)) -> 45.446751 | E20: =IF(A20="Ground","—",IF(A20="","",E19 + D20)) -> 190.23278 | F20: =IF(A20="Ground","—",IF(A20="","",E20/C20)) -> 0.13011818 | G20: =IF(A20="Ground","—",IF(A20="","",F20*B20)) -> 72.345707 | H20: =IF(A20="Ground","—",IF(A20="","",0.2*$C$12*$F$12*B20)) -> 75.304077 | I20: =IF(A20="Ground","—",IF(A20="","",0.4*$C$12*$F$12*B20)) -> 150.60815 | J20: =IF(A20="Ground","—",IF(A20="","",IF(I20<MAX(G20,H20),I20,MAX(G20,H20)))) -> 75.304077 | K20: =IF(A20="Ground","—",IF(A20="","",J20/B20)) -> 0.13543899
A21: =+'Vertical Distribution'!C27 -> 2 | B21: =IF(A21="Ground","—",IF(A21="","",'Vertical Distribution'!F27)) -> 560 | C21: =IF(A21="Ground","—",IF(A21="","",C20 + B21)) -> 2022 | D21: =IF(A21="Ground","—",IF(A21="","",'Vertical Distribution'!I27)) -> 19.378969 | E21: =IF(A21="Ground","—",IF(A21="","",E20 + D21)) -> 209.61175 | F21: =IF(A21="Ground","—",IF(A21="","",E21/C21)) -> 0.10366555 | G21: =IF(A21="Ground","—",IF(A21="","",F21*B21)) -> 58.052709 | H21: =IF(A21="Ground","—",IF(A21="","",0.2*$C$12*$F$12*B21)) -> 75.845833 | I21: =IF(A21="Ground","—",IF(A21="","",0.4*$C$12*$F$12*B21)) -> 151.69167 | J21: =IF(A21="Ground","—",IF(A21="","",IF(I21<MAX(G21,H21),I21,MAX(G21,H21)))) -> 75.845833 | K21: =IF(A21="Ground","—",IF(A21="","",J21/B21)) -> 0.13543899
A22: =+'Vertical Distribution'!C28 -> Ground | B22: =IF(A22="Ground","—",IF(A22="","",'Vertical Distribution'!F28)) -> — | C22: =IF(A22="Ground","—",IF(A22="","",C21 + B22)) -> — | D22: =IF(A22="Ground","—",IF(A22="","",'Vertical Distribution'!I28)) -> — | E22: =IF(A22="Ground","—",IF(A22="","",E21 + D22)) -> — | F22: =IF(A22="Ground","—",IF(A22="","",E22/C22)) -> — | G22: =IF(A22="Ground","—",IF(A22="","",F22*B22)) -> — | H22: =IF(A22="Ground","—",IF(A22="","",0.2*$C$12*$F$12*B22)) -> — | I22: =IF(A22="Ground","—",IF(A22="","",0.4*$C$12*$F$12*B22)) -> — | J22: =IF(A22="Ground","—",IF(A22="","",IF(I22<MAX(G22,H22),I22,MAX(G22,H22)))) -> — | K22: =IF(A22="Ground","—",IF(A22="","",J22/B22)) -> —
A23: =+'Vertical Distribution'!C29 | B23: =IF(A23="Ground","—",IF(A23="","",'Vertical Distribution'!F29)) | C23: =IF(A23="Ground","—",IF(A23="","",C22 + B23)) | D23: =IF(A23="Ground","—",IF(A23="","",'Vertical Distribution'!I29)) | E23: =IF(A23="Ground","—",IF(A23="","",E22 + D23)) | F23: =IF(A23="Ground","—",IF(A23="","",E23/C23)) | G23: =IF(A23="Ground","—",IF(A23="","",F23*B23)) | H23: =IF(A23="Ground","—",IF(A23="","",0.2*$C$12*$F$12*B23)) | I23: =IF(A23="Ground","—",IF(A23="","",0.4*$C$12*$F$12*B23)) | J23: =IF(A23="Ground","—",IF(A23="","",IF(I23<MAX(G23,H23),I23,MAX(G23,H23)))) | K23: =IF(A23="Ground","—",IF(A23="","",J23/B23))
A24: =+'Vertical Distribution'!C30 | B24: =IF(A24="Ground","—",IF(A24="","",'Vertical Distribution'!F30)) | C24: =IF(A24="Ground","—",IF(A24="","",C23 + B24)) | D24: =IF(A24="Ground","—",IF(A24="","",'Vertical Distribution'!I30)) | E24: =IF(A24="Ground","—",IF(A24="","",E23 + D24)) | F24: =IF(A24="Ground","—",IF(A24="","",E24/C24)) | G24: =IF(A24="Ground","—",IF(A24="","",F24*B24)) | H24: =IF(A24="Ground","—",IF(A24="","",0.2*$C$12*$F$12*B24)) | I24: =IF(A24="Ground","—",IF(A24="","",0.4*$C$12*$F$12*B24)) | J24: =IF(A24="Ground","—",IF(A24="","",IF(I24<MAX(G24,H24),I24,MAX(G24,H24)))) | K24: =IF(A24="Ground","—",IF(A24="","",J24/B24))
A25: =+'Vertical Distribution'!C31 | B25: =IF(A25="Ground","—",IF(A25="","",'Vertical Distribution'!F31)) | C25: =IF(A25="Ground","—",IF(A25="","",C24 + B25)) | D25: =IF(A25="Ground","—",IF(A25="","",'Vertical Distribution'!I31)) | E25: =IF(A25="Ground","—",IF(A25="","",E24 + D25)) | F25: =IF(A25="Ground","—",IF(A25="","",E25/C25)) | G25: =IF(A25="Ground","—",IF(A25="","",F25*B25)) | H25: =IF(A25="Ground","—",IF(A25="","",0.2*$C$12*$F$12*B25)) | I25: =IF(A25="Ground","—",IF(A25="","",0.4*$C$12*$F$12*B25)) | J25: =IF(A25="Ground","—",IF(A25="","",IF(I25<MAX(G25,H25),I25,MAX(G25,H25)))) | K25: =IF(A25="Ground","—",IF(A25="","",J25/B25))
A26: =+'Vertical Distribution'!C32 | B26: =IF(A26="Ground","—",IF(A26="","",'Vertical Distribution'!F32)) | C26: =IF(A26="Ground","—",IF(A26="","",C25 + B26)) | D26: =IF(A26="Ground","—",IF(A26="","",'Vertical Distribution'!I32)) | E26: =IF(A26="Ground","—",IF(A26="","",E25 + D26)) | F26: =IF(A26="Ground","—",IF(A26="","",E26/C26)) | G26: =IF(A26="Ground","—",IF(A26="","",F26*B26)) | H26: =IF(A26="Ground","—",IF(A26="","",0.2*$C$12*$F$12*B26)) | I26: =IF(A26="Ground","—",IF(A26="","",0.4*$C$12*$F$12*B26)) | J26: =IF(A26="Ground","—",IF(A26="","",IF(I26<MAX(G26,H26),I26,MAX(G26,H26)))) | K26: =IF(A26="Ground","—",IF(A26="","",J26/B26))
A27: =+'Vertical Distribution'!C33 | B27: =IF(A27="Ground","—",IF(A27="","",'Vertical Distribution'!F33)) | C27: =IF(A27="Ground","—",IF(A27="","",C26 + B27)) | D27: =IF(A27="Ground","—",IF(A27="","",'Vertical Distribution'!I33)) | E27: =IF(A27="Ground","—",IF(A27="","",E26 + D27)) | F27: =IF(A27="Ground","—",IF(A27="","",E27/C27)) | G27: =IF(A27="Ground","—",IF(A27="","",F27*B27)) | H27: =IF(A27="Ground","—",IF(A27="","",0.2*$C$12*$F$12*B27)) | I27: =IF(A27="Ground","—",IF(A27="","",0.4*$C$12*$F$12*B27)) | J27: =IF(A27="Ground","—",IF(A27="","",IF(I27<MAX(G27,H27),I27,MAX(G27,H27)))) | K27: =IF(A27="Ground","—",IF(A27="","",J27/B27))
A28: =+'Vertical Distribution'!C34 | B28: =IF(A28="Ground","—",IF(A28="","",'Vertical Distribution'!F34)) | C28: =IF(A28="Ground","—",IF(A28="","",C27 + B28)) | D28: =IF(A28="Ground","—",IF(A28="","",'Vertical Distribution'!I34)) | E28: =IF(A28="Ground","—",IF(A28="","",E27 + D28)) | F28: =IF(A28="Ground","—",IF(A28="","",E28/C28)) | G28: =IF(A28="Ground","—",IF(A28="","",F28*B28)) | H28: =IF(A28="Ground","—",IF(A28="","",0.2*$C$12*$F$12*B28)) | I28: =IF(A28="Ground","—",IF(A28="","",0.4*$C$12*$F$12*B28)) | J28: =IF(A28="Ground","—",IF(A28="","",IF(I28<MAX(G28,H28),I28,MAX(G28,H28)))) | K28: =IF(A28="Ground","—",IF(A28="","",J28/B28))
A29: =+'Vertical Distribution'!C35 | B29: =IF(A29="Ground","—",IF(A29="","",'Vertical Distribution'!F35)) | C29: =IF(A29="Ground","—",IF(A29="","",C28 + B29)) | D29: =IF(A29="Ground","—",IF(A29="","",'Vertical Distribution'!I35)) | E29: =IF(A29="Ground","—",IF(A29="","",E28 + D29)) | F29: =IF(A29="Ground","—",IF(A29="","",E29/C29)) | G29: =IF(A29="Ground","—",IF(A29="","",F29*B29)) | H29: =IF(A29="Ground","—",IF(A29="","",0.2*$C$12*$F$12*B29)) | I29: =IF(A29="Ground","—",IF(A29="","",0.4*$C$12*$F$12*B29)) | J29: =IF(A29="Ground","—",IF(A29="","",IF(I29<MAX(G29,H29),I29,MAX(G29,H29)))) | K29: =IF(A29="Ground","—",IF(A29="","",J29/B29))
A30: =+'Vertical Distribution'!C36 | B30: =IF(A30="Ground","—",IF(A30="","",'Vertical Distribution'!F36)) | C30: =IF(A30="Ground","—",IF(A30="","",C29 + B30)) | D30: =IF(A30="Ground","—",IF(A30="","",'Vertical Distribution'!I36)) | E30: =IF(A30="Ground","—",IF(A30="","",E29 + D30)) | F30: =IF(A30="Ground","—",IF(A30="","",E30/C30)) | G30: =IF(A30="Ground","—",IF(A30="","",F30*B30)) | H30: =IF(A30="Ground","—",IF(A30="","",0.2*$C$12*$F$12*B30)) | I30: =IF(A30="Ground","—",IF(A30="","",0.4*$C$12*$F$12*B30)) | J30: =IF(A30="Ground","—",IF(A30="","",IF(I30<MAX(G30,H30),I30,MAX(G30,H30)))) | K30: =IF(A30="Ground","—",IF(A30="","",J30/B30))
B32: Minimum Fpx = 0.2 SDS Ie wpx per Eq. 12.10-2
B34: Maximum Fpx = 0.4 SDS Ie wpx per Eq. 12.10-3
B36: Diaphragm forces from the structural analysis and diaphragm forces from the transfer of forces from
B37: above/below the diaphragm are determined separately.
